<?xml version="1.0"?>
<!-- Copyright (c) 2016 The UUV Simulator Authors.
     All rights reserved.

     Licensed under the Apache License, Version 2.0 (the "License");
     you may not use this file except in compliance with the License.
     You may obtain a copy of the License at

       http://www.apache.org/licenses/LICENSE-2.0

     Unless required by applicable law or agreed to in writing, software
     distributed under the License is distributed on an "AS IS" BASIS,
     WITHOUT WARRANTIES OR CONDITIONS OF ANY KIND, either express or implied.
     See the License for the specific language governing permissions and
     limitations under the License.
-->
<robot xmlns:xacro="http://www.ros.org/wiki/xacro" >
  <!-- Import macro files -->
  <xacro:include filename="$(find uuv_descriptions)/urdf/common.urdf.xacro" />
  <xacro:include filename="$(find uuv_sensor_ros_plugins)/urdf/sensor_snippets.xacro"/>
  <xacro:include filename="$(find uuv_gazebo_ros_plugins)/urdf/snippets.xacro"/>

  <!-- Properties -->
  <xacro:property name="mass" value="69.25"/>
  <xacro:property name="fluid_density" value="1024.0"/>
  <xacro:property name="gravity" value="9.81"/>
  <xacro:property name="cob" value="0 0 0"/>
  <xacro:property name="cog" value="0 0 0.0054"/>

  <xacro:property name="visual_mesh_file" value="file://$(find glider_hybrid_whoi_description)/mesh/glider_slocum/Slocum-Glider.dae" />
  <xacro:property name="collision_mesh_file" value="file://$(find glider_hybrid_whoi_description)/mesh/glider_slocum/COLLISION-Slocum-Glider.dae" />
  <xacro:property name="prop_mesh_file" value="file://$(find glider_hybrid_whoi_description)/mesh/glider_slocum/Slocum-Glider-Propeller.dae" />
  <!-- <xacro:property name="left_fin_mesh_file" value="file://$(find glider_hybrid_whoi_description)/mesh/glider_slocum/Slocum-Glider-LeftFin.dae" /> -->
  <!-- <xacro:property name="right_fin_mesh_file" value="file://$(find glider_hybrid_whoi_description)/mesh/glider_slocum/Slocum-Glider-RightFin.dae" /> -->
  
  <xacro:macro name="glider_hybrid_whoi_base" params="namespace debug inertial_reference_frame">
    <!-- Base_link of the model -->
    <link name="${namespace}/base_link">
      <visual>
        <origin xyz="0 0 0" rpy="0 0 -${0.5*pi}" />
        <geometry>
          <mesh filename="${visual_mesh_file}" scale="1 1 1" />
        </geometry>
      </visual>
      <collision>
        <origin xyz="0 0 0" rpy="0 0 -${0.5*pi}" />
        <geometry>
          <mesh filename="${collision_mesh_file}" scale="1 1 1" />
        </geometry>
      </collision>
      <inertial>
        <mass value="${mass}"/>
        <origin xyz="0 0 0" rpy="0 0 0" />
        <inertia ixx="10" ixy="0" ixz="0" iyy="10" iyz="0" izz="10" />
      </inertial>
    </link>

    <!-- Dummy propeller plugin properties (rotorConstant = 0) -->
    <!-- This is for topics used to visualize the propeller roatation  -->
    <xacro:property name="dummy_plugin_properties_for_visual_rotation">
      <dynamics>
        <type>FirstOrder</type>
        <timeConstant>0.1</timeConstant>
      </dynamics>
      <conversion>
        <type>Basic</type>
        <rotorConstant>4.9e-05</rotorConstant>
      </conversion>
    </xacro:property>
    <xacro:property name="dummy_link_properties_for_visual_rotation">
      <xacro:box_inertial x="0" y="0" z="0" mass="0.00001">
        <origin xyz="0 0 0" rpy="0 0 0"/>
      </xacro:box_inertial>
      <collision>
        <geometry>
          <cylinder length="0.000001" radius="0.000001"/>
        </geometry>
        <origin xyz="0 0 0" rpy="0 0 0"/>
      </collision>
    </xacro:property>

    <!-- First propeller -->
    <xacro:property name="thruster_id" value="1"/>
    <joint name="${namespace}/thruster_${thruster_id}_joint" type="continuous">
      <origin xyz="0.0 0.0 0" rpy="0 0 0"/>
      <axis xyz="1 0 0"/>
      <parent link="${namespace}/base_link"/>
      <child link="${namespace}/thruster_${thruster_id}"/>
    </joint>
    <link name="${namespace}/thruster_${thruster_id}">
      <xacro:insert_block name="dummy_link_properties_for_visual_rotation"/>
      <visual>
        <origin xyz="0 0 0" rpy="0 0 -${0.46*pi}"/>
        <geometry>
          <mesh filename="${prop_mesh_file}" scale="1 1 1"/>
        </geometry>
      </visual>
    </link>
    <gazebo>
      <plugin name="${namespace}_${thruster_id}_thruster_model" filename="libuuv_thruster_ros_plugin.so">
        <linkName>${namespace}/thruster_${thruster_id}</linkName>
        <jointName>${namespace}/thruster_${thruster_id}_joint</jointName>
        <thrusterID>${thruster_id}</thrusterID>
        <xacro:insert_block name="dummy_plugin_properties_for_visual_rotation"/>
      </plugin>
    </gazebo>
    <gazebo reference="${namespace}/thruster_${thruster_id}">
      <selfCollide>false</selfCollide>
    </gazebo>

    <!-- add a small cube to repersent a hydrophone on the gliders wing -->
    <xacro:property name="hydrophone_4_id" value="4"/>
    <link name="${namespace}/hydrophone_${hydrophone_4_id}">
      <visual>
        <geometry>
          <box size="0.2 0.05 0.05"/>
        </geometry>
      </visual>
      <collision>
        <geometry>
          <box size="0.2 0.05 0.05"/>
        </geometry>
      </collision>
      <inertial>
        <mass value="0.5"/>
        <inertia ixx="0.1" ixy="0" ixz="0" iyy="0.1" iyz="0" izz="0.1"/>
      </inertial>
    </link>
    <joint name="${namespace}/hydrophone_${hydrophone_4_id}_joint" type="continuous">
      <origin xyz="-0.3 1.1 0.03" rpy="0 0 0"/>
      <parent link="${namespace}/base_link"/>
      <child link="${namespace}/hydrophone_${hydrophone_4_id}"/>
    </joint>
    <gazebo reference="$hydrophone_${hydrophone_4_id}">
      <selfCollide>false</selfCollide>
    </gazebo>

    <!-- add a small cube to repersent a hydrophone on the gliders wing -->
    <link name="${namespace}/hydrophone_3">
      <visual>
        <geometry>
          <box size="0.2 0.05 0.05"/>
        </geometry>
      </visual>
      <collision>
        <geometry>
          <box size="0.2 0.05 0.05"/>
        </geometry>
      </collision>
      <inertial>
        <mass value="0.5"/>
        <inertia ixx="0.1" ixy="0" ixz="0" iyy="0.1" iyz="0" izz="0.1"/>
      </inertial>
    </link>
    <joint name="${namespace}/hydrophone_3_joint" type="continuous">
      <origin xyz="-0.3 -1.1 0.03" rpy="0 0 0"/>
      <parent link="${namespace}/base_link"/>
      <child link="${namespace}/hydrophone_3"/>
    </joint>

      <!-- add a small cube to repersent a hydrophone on the gliders wing -->
    <link name="${namespace}/hydrophone_1">
      <visual>
        <geometry>
          <box size="0.3 0.1 0.1"/>
        </geometry>
      </visual>
      <collision>
        <geometry>
          <box size="0.3 0.1 0.1"/>
        </geometry>
      </collision>
      <inertial>
        <mass value="0.8"/>
        <inertia ixx="0.1" ixy="0" ixz="0" iyy="0.1" iyz="0" izz="0.1"/>
      </inertial>
    </link>
    <joint name="${namespace}/hydrophone_1_joint" type="continuous">
      <origin xyz="1.0 0.0 0.25" rpy="0 0 0"/>
      <parent link="${namespace}/base_link"/>
      <child link="${namespace}/hydrophone_1"/>
    </joint>

        <!-- add a small cube to repersent a hydrophone on the gliders wing -->
    <link name="${namespace}/hydrophone_2">
      <visual>
        <geometry>
          <box size="0.2 0.05 0.05"/>
        </geometry>
      </visual>
      <collision>
        <geometry>
          <box size="0.2 0.05 0.05"/>
        </geometry>
      </collision>
      <inertial>
        <mass value="0.5"/>
        <inertia ixx="0.1" ixy="0" ixz="0" iyy="0.1" iyz="0" izz="0.1"/>
      </inertial>
    </link>
    <joint name="${namespace}/hydrophone_2_joint" type="continuous">
      <origin xyz="-1.0 0.0 0.25" rpy="0 0 0"/>
      <parent link="${namespace}/base_link"/>
      <child link="${namespace}/hydrophone_2"/>
    </joint>

    <!-- Kinematics Plugin -->
    <gazebo>
      <plugin name="${namespace}_kinematics_plugin"
              filename="libkinematics_ros_plugin.so">
        <fluid_deisnty>${fluid_density}</fluid_deisnty>
        <writeLog>true</writeLog>
        <flow_velocity_topic>/hydrodynamics/current_velocity/${namespace}</flow_velocity_topic>
        <use_global_ocean_current>true</use_global_ocean_current>
        <!-- Kinematics coefficients -->
        <f_pitch_battpos_cal_m>1.2565</f_pitch_battpos_cal_m>
        <f_pitch_battpos_cal_b>-0.055</f_pitch_battpos_cal_b>
        <Area>0.345</Area>
        <C_D>0.2534</C_D>
        <C_L>0.4160</C_L>
        <f_thruster_voltage_v1>1.8953</f_thruster_voltage_v1>
        <f_thruster_voltage_v2>-1.995</f_thruster_voltage_v2>
        <f_thruster_voltage_v3>1.8701</f_thruster_voltage_v3>
        <f_thruster_power_w1>-0.020919</f_thruster_power_w1>
        <f_thruster_power_w2>1.4699</f_thruster_power_w2>
        <f_thruster_power_w3>0.97895</f_thruster_power_w3>
      </plugin>
      <plugin name="{namespace}_dave_ocean_current_plugin" filename="libdave_ocean_current_model_plugin.so">
        <flow_velocity_topic>hydrodynamics/current_velocity/${namespace}</flow_velocity_topic>
        <base_link_name>${namespace}/base_link</base_link_name>
        <transient_current>
          <topic_stratified_database>stratified_current_velocity_database</topic_stratified_database>
          <velocity_north>
            <noiseAmp>0.7</noiseAmp>
            <noiseFreq>0.1</noiseFreq>
          </velocity_north>
          <velocity_east>
            <noiseAmp>0.7</noiseAmp>
            <noiseFreq>0.1</noiseFreq>
          </velocity_east>
          <velocity_down>
            <noiseAmp>0.7</noiseAmp>
            <noiseFreq>0.1</noiseFreq>
          </velocity_down>
        </transient_current>
        <tide_oscillation>true</tide_oscillation>
      </plugin>
    </gazebo>

    <gazebo>
      <plugin name="gazebo_ros_control" filename="libgazebo_ros_control.so">
        <robotNamespace>/${namespace}</robotNamespace>
        <robotParam>/${namespace}/robot_description</robotParam>

        <bathymetry>
          <interval_s>1.0</interval_s>
        </bathymetry>

      </plugin>
    </gazebo>

    <!-- TODO: Parametrize the battery unit -->
    <xacro:basic_linear_battery_macro
      namespace="${namespace}"
      parent_link="${namespace}/base_link"
      prefix=""
      open_circuit_voltage_constant_coef="3.7"
      open_circuit_voltage_linear_coef="-3.1424"
      initial_charge="1.1665"
      capacity="0.5"
      resistance="0.002"
      smooth_current_tau="1.9499"
      voltage="4.2"
      update_rate="2.0"/>

    <xacro:include filename="$(find glider_hybrid_whoi_description)/urdf/glider_hybrid_whoi_sensors_kinematics.xacro"/>

  </xacro:macro>
</robot>
